% python classes slides - exceptions
% (c) 2012 Kostiantyn Danylov aka koder 
% koder.mail@gmail.com
% distributed under CC-BY licence
% http://creativecommons.org/licenses/by/3.0/deed.en

\documentclass{article}
\input{files/lectures_env}
\input{files/python_cmds}

\begin{document}
\LARGE

%-------------------------------------------------------------------------------
\begin{lstlisting}
    x = int(input("Enter number"))
    y = int(input("Enter divider"))
    if y == 0:
        print "Divider can't be zero"
    else:
        print "{}/{} == {}".format(x, y, x / y)
\end{lstlisting}
\newpage

%-------------------------------------------------------------------------------
\begin{lstlisting}
	def get_params():
	    x = int(input("Enter number"))
	    y = int(input("Enter divider"))
	    return x, y
	    
	def get_result(x, y):
	    if y == 0:
	        return None
	    else:
	        return x / y
	
	def main():
	    x, y = get_params()
	    res = get_result()
	    if res is None:
	        print "Wrong data"
	    else:
	        print "res =", res
\end{lstlisting}
\newpage

%-------------------------------------------------------------------------------
Модуляризация программы приводит к разнесению точки, где можно обнаружить ошибку
и точки, где ее можно обработать. Задача - найти общий метод доставки информации 
о ошибке от точки обнаружения до точки обработки.
\newpage

%-------------------------------------------------------------------------------
\begin{center} 70е (а также 2013 - haskell, fp scala, Go \& Co) \end{center}
\begin{itemize}
	\item Для каждой функции выделить специальное значение - признак ошибки;
	\item Проверять результат каждой функции, обрабатывать ошибку
	        или передавать ее дальше, если обработка в текущей точке невозможна;
	\item Как вариант функция всегда возвращает код ошибки, а настоящий 
	        результат идет по ссылке (POSIX/MSAPI).
\end{itemize}
\begin{lstlisting}
	def do_some_work(name, vals):
		if not isinstance(name, basestring):
			return None
		#......
		return res

	def f2():
		res = do_some_work("1231", [1, 2])
		if res is None:
			return None
		.....
\end{lstlisting}
\newpage

%-------------------------------------------------------------------------------
\begin{center} Проблемы \end{center}
\begin{itemize}
	\item Нужно помнить какое значение возвращает функция при ошибке (MSAPI);
	\item Нужно хранить дополнительно информацию о ошибке;
	\item Информация о контексте ошибки ограничена.
\end{itemize}
\newpage

%-------------------------------------------------------------------------------
\begin{center} Решение \end{center}
\begin{itemize}
	\item Возвращать из каждой функции тройку (is\_ok, traceback\_or\_None, result\_or\_error);
	\item Превратить return res в return (True, None, result);
	\item Превратить return err в return (False, [curr\_func\_name], err\_description);
	\item В обработчиках ошибок нужно фильтровать ошибки по типу;
	\item Проверять на выходе из каждой функции результат;
	\item Если не проверить ошибку, то проблема 
			возникнет в непредсказуемом месте кода.
\end{itemize}
\newpage

%-------------------------------------------------------------------------------
\begin{lstlisting}
	def do_some_work(name, vals):
		if not isinstance(name, basestring):
			return (False, ["do_some_work"], "name should be a string")
		#......
		return (True, None, res)

	def f2():
		is_ok, stack, res = do_some_work("1231", [1, 2])
		if not is_ok:
			return (False, stack + ["f2"], res)
		.....
\end{lstlisting}
\newpage

%-------------------------------------------------------------------------------
\begin{center}Уже лучше, но:\end{center}
\begin{itemize}
	\item Загрязняет код;
	\item Для каждого вызова отдельная строка и свой if;
	\item Такие ошибки часто не проверяются (printf);
	\item
	\item Вспомагательный код очень простой - его 
		  генерацию можно переложить на компилятор.
\end{itemize}
\newpage

%-------------------------------------------------------------------------------
\begin{center} Именно это и делают современные языки \end{center}
\begin{center} Исключения \end{center}
\begin{figure}[ht]
\begin{minipage}[b]{0.45\linewidth}
\Large
\begin{lstlisting}
	def x1(a, b):
		if 0 == b:
			return (False, 
				    ["x1"],
				    ZeroDiv)

	def x2(a, b):
		print a,b
		ok, res, stack = x1(a, b)
		if not ok:
			return (False, 
					stack + \
					["x2"],
					res)

	ok, stack, res = x1(a, b)
	if not ok and res is ZeroDiv:
		#process
\end{lstlisting}
\end{minipage}
\hspace{2cm}
\begin{minipage}[b]{0.45\linewidth}
\Large
\begin{lstlisting}
	def x1(a, b):
		if 0 == b:
			raise ZeroDivisionError()



	def x2(a, b):
		print a,b
		return x1(a, b)




	try:
		res = x1(a, b)
	except ZeroDivisionError:
		#process
\end{lstlisting}
\end{minipage}
\end{figure}
\newpage

%-------------------------------------------------------------------------------
\begin{center} Исключения \end{center}
\begin{itemize}
	\item Исключение – это событие, после которого дальнейшее продолжение 
			работы в данной точке не возможно. По итогу такого события 
			генерируется объект-исключение, и исполнение передается соответствующему 
			обработчику ошибок;
	\item Пример – деление на 0, выбрасывается ошибка ZeroDivisionError;
	\item Исключения помогают упростить код, убрав из него множество 
			проверок и значительно облегчить восстановление программы после сбоя;
	\item Типы всех исключений наследуют Exception (кроме KeyboardInterrupt, GeneratorExit, SystemExit);
	\item Чаще всего принимают строку как параметр.
\end{itemize}
\newpage

%-------------------------------------------------------------------------------

\begin{center} Исключения \end{center}
\begin{lstlisting}
	try:
		block1
	except tp2 as var2:
		block2
	except (tp3, tp4) as var3:
		block3
	else:
		block5
	finally:
		block4
\end{lstlisting}
\newpage

%-------------------------------------------------------------------------------
\begin{center} Исключения \end{center}
\begin{lstlisting}
	try:
		raise tp2("xxx")  # <<<<
	except tp2 as var2:
		block2            # <<<<
	except (tp3, tp4) as var3:
		block3
	else:
		block5
	finally:
		block4            # <<<<
\end{lstlisting}
\newpage

%-------------------------------------------------------------------------------
\begin{center} Исключения \end{center}
\begin{lstlisting}
	try:
		pass           # <<<
	except tp2 as var2:
		block2
	except (tp3, tp4) as var3:
		block3
	else:
		block5         # <<<
	finally:
		block4         # <<<
\end{lstlisting}
\newpage

%-------------------------------------------------------------------------------
\begin{center} Исключения \end{center}
\begin{lstlisting}
	def f1(t, d, x, y):
		if t – d  == 0:
		    return None
		else:
		    t1 = ((x + y) / (t - d))
		    if t1 == 0:
		        return None
		    else:
		        return 1 / ((x + y) / (t - d))

	def f2(t, d, x, y):
		try:
		    return 1 / ((x + y) / (t - d))
		except ZeroDivisionError:
		    return None
\end{lstlisting}
\newpage

%-------------------------------------------------------------------------------
\begin{center} Исключения. raise \end{center}
\begin{itemize}
	\item \lstinline!raise ExceptionType(....)! порождает исключение
	\item \lstinline!ExceptionType! должно наследовать \lstinline!Exception!
	\item \lstinline!raise! без параметров разрешено только в блоке except. 
		При этом повторно выбрасывается текущее исключение
\end{itemize}
\begin{lstlisting}
	try:
		func()
	except Exception:
		print "func cause exception"
		raise
\end{lstlisting}
\newpage

%-------------------------------------------------------------------------------
\begin{center} Стандартные исключения \end{center}
\newpage

%-------------------------------------------------------------------------------
\begin{center} Исключения. traceback \end{center}
	В обработчике исключения \lstinline!sys.exc_info()! возвращает тройку
		(Тип исключения, Объект исключения, Состояние Стека)
\begin{lstlisting}
	try:
	    raise ValueError("ddd")
	except Exception as x:
		tb = sys.exc_info()[2]

	print tb.tb_frame # <frame at 0x....>
	print tb.tb_frame.f_lineno # 4
	print tb.tb_frame.f_code.co_name # '<module>'
	print tb.tb_frame.f_code.co_filename 
		# '<ipython-input-7-492d537cf800>'
	print tb.tb_next # <frame at 0x....> or None
	del tb
\end{lstlisting}
\newpage

%-------------------------------------------------------------------------------
\begin{center} Гарантии безопасности исключений \end{center}
\begin{lstlisting}
	class TimedCallbackStack(object):
		def __init__(self, tf):
			self.cb_list = []
			self.tf = tf
			self.sum_time = 0.0

		def pop_and_exec(self):
			func = self.cb_list.pop()
			t = self.tf()
			res = func()
			self.sum_time += self.tf() - t
			return res
\end{lstlisting}

%-------------------------------------------------------------------------------
\begin{center} Другие проблемы исключений \end{center}
\begin{itemize}
	\item Выполнение функции может прерваться в любой точке - нужно работать со всеми ресурсами
	      через try/finally или, лучше через with.
	\item try/finally/with делают из линейного кода вложенный
	\item Для не локальных объектов все печально
	\item Все равно нужно помнить какие исключения порождает конкретная функция
	      (хотя все не так плохо, как с "исключениями" из 70х)
\end{itemize}
\newpage

%-------------------------------------------------------------------------------
\end{document}

